Workbook

Sheet Dashboard
A1: H | B1: HYBRIDFUELCO | I1: PROGRESS TRACKER | N1: =IFERROR(LOOKUP(2,1/(Weight!$B$4:$B$30<>""),Weight!$B$4:$B$30),"") -> 87
N2: =IFERROR(LOOKUP(2,1/(Weight!$C$4:$C$30<>""),Weight!$C$4:$C$30),"") -> -0.2
N3: =IF(AND(N1<>"",N2<>""),N2/N1,"") -> -0.0022988506
A4: Current weight | D4: Last change | G4: Status | J4: Today
A5: =N1 -> 87 | D5: =N2 -> -0.2 | G5: =IF(N3="","",IF(N3<-0.01,"! Too fast",IF(N3<-0.003,"✓ On track",IF(N3<=0.003,"– Stable",IF(N3<=0.01,"✓ On track","! Too fast"))))) -> – Stable | J5: =SUMIFS('Meal plan'!$E$4:$E$31,'Meal plan'!$A$4:$A$31,$K$8) -> 2490
A8: Weight trend | G8: Today — meals | K8: Mon
G9: ✓ | H9: Breakfast | I9: =IFERROR(INDEX('Meal plan'!$C$4:$C$31,MATCH($K$8&"|"&"Breakfast",'Meal plan'!$I$4:$I$31,0)),"") -> Savoury Oats with Egg | L9: =IFERROR(INDEX('Meal plan'!$E$4:$E$31,MATCH($K$8&"|"&"Breakfast",'Meal plan'!$I$4:$I$31,0)),"") -> 536
G10: ✓ | H10: Lunch | I10: =IFERROR(INDEX('Meal plan'!$C$4:$C$31,MATCH($K$8&"|"&"Lunch",'Meal plan'!$I$4:$I$31,0)),"") -> Skyr Bowl with Salmon & Rice | L10: =IFERROR(INDEX('Meal plan'!$E$4:$E$31,MATCH($K$8&"|"&"Lunch",'Meal plan'!$I$4:$I$31,0)),"") -> 741
G11: ✓ | H11: Dinner | I11: =IFERROR(INDEX('Meal plan'!$C$4:$C$31,MATCH($K$8&"|"&"Dinner",'Meal plan'!$I$4:$I$31,0)),"") -> Salmon & Quinoa Clean Bowl | L11: =IFERROR(INDEX('Meal plan'!$E$4:$E$31,MATCH($K$8&"|"&"Dinner",'Meal plan'!$I$4:$I$31,0)),"") -> 741
G12: ✓ | H12: Snack | I12: =IFERROR(INDEX('Meal plan'!$C$4:$C$31,MATCH($K$8&"|"&"Snack",'Meal plan'!$I$4:$I$31,0)),"") -> Quark with Banana & Oats | L12: =IFERROR(INDEX('Meal plan'!$E$4:$E$31,MATCH($K$8&"|"&"Snack",'Meal plan'!$I$4:$I$31,0)),"") -> 472
G13: Day total | J13: =SUMIFS('Meal plan'!$E$4:$E$31,'Meal plan'!$A$4:$A$31,$K$8) -> 2490
A16: =IF(N3="","Responsible pace — ~0.5–1% per week. This protects muscle and recovery.",IF(OR(N3<-0.01,N3>0.01),"You're changing faster than 1% per week. Adjust your calories a bit.",IF(N3>-0.003,"Little change. Be patient, or adjust your calories slightly.","Responsible pace — ~0.5–1% per week. This protects muscle and recovery."))) -> Little change. Be patient, or adjust your calories slightly.
A18: Daily macros — selected day
A19: Protein | E19: Carbs | I19: Fat
A20: =SUMIFS('Meal plan'!$F$4:$F$31,'Meal plan'!$A$4:$A$31,$K$8) -> 181 | E20: =SUMIFS('Meal plan'!$G$4:$G$31,'Meal plan'!$A$4:$A$31,$K$8) -> 256 | I20: =SUMIFS('Meal plan'!$H$4:$H$31,'Meal plan'!$A$4:$A$31,$K$8) -> 72

Sheet Meal plan
A1: MEAL PLAN
A2: Replace this example week with your own plan from the app. The dashboard reads 'Today' from here.
A3: Day | B3: Type | C3: Dish | D3: Ingredients | E3: kcal | F3: Protein (g) | G3: Carbs (g) | H3: Fat (g) | I3: key
A4: Mon | B4: Breakfast | C4: Savoury Oats with Egg | D4: 64g Oats, 192g Low-fat stock, 128g Fresh spinach, 64g Egg (poached), 19g Pumpkin seeds | E4: 536 | F4: 28 | G4: 54 | H4: 20 | I4: =$A4&"|"&$B4 -> Mon|Breakfast
A5: Mon | B5: Lunch | C5: Skyr Bowl with Salmon & Rice | D5: 192g Salmon fillet, 255g Skyr (plain), 230g White rice (cooked), 128g Cucumber | E5: 741 | F5: 66 | G5: 79 | H5: 18 | I5: =$A5&"|"&$B5 -> Mon|Lunch
A6: Mon | B6: Dinner | C6: Salmon & Quinoa Clean Bowl | D6: 160g Salmon fillet, 77g Quinoa (dry), 128g Broccoli (steamed), 64g Edamame, 13g Olive oil | E6: 741 | F6: 49 | G6: 57 | H6: 28 | I6: =$A6&"|"&$B6 -> Mon|Dinner
A7: Mon | B7: Snack | C7: Quark with Banana & Oats | D7: 319g Quark (low-fat), 153g Banana, 38g Oats | E7: 472 | F7: 38 | G7: 66 | H7: 6 | I7: =$A7&"|"&$B7 -> Mon|Snack
A8: Tue | B8: Breakfast | C8: High-Protein Pancakes | D8: 46g Oat flour, 35g Pea protein powder, 58g Egg, 115g Skimmed milk | E8: 496 | F8: 40 | G8: 44 | H8: 10 | I8: =$A8&"|"&$B8 -> Tue|Breakfast
A9: Tue | B9: Lunch | C9: Tofu & Veggie Miso Bowl | D9: 231g Firm tofu, 92g Edamame, 173g Courgette, 12g Sesame oil, 17g Miso paste | E9: 554 | F9: 44 | G9: 42 | H9: 23 | I9: =$A9&"|"&$B9 -> Tue|Lunch
A10: Tue | B10: Dinner | C10: Vegan Lentil-Chickpea Curry | D10: 115g Lentils (tinned), 115g Chickpeas (tinned), 173g Chopped tomatoes, 58g Light coconut milk, 35g Kale | E10: 589 | F10: 30 | G10: 67 | H10: 17 | I10: =$A10&"|"&$B10 -> Tue|Dinner
A11: Tue | B11: Snack | C11: Skyr with Berries & Quark | D11: 231g Skyr (plain), 115g Quark (low-fat), 115g Mixed berries | E11: 381 | F11: 44 | G11: 32 | H11: 7 | I11: =$A11&"|"&$B11 -> Tue|Snack
A12: Wed | B12: Breakfast | C12: Savoury Oats with Egg | D12: 64g Oats, 192g Low-fat stock, 128g Fresh spinach, 64g Egg (poached), 19g Pumpkin seeds | E12: 536 | F12: 28 | G12: 54 | H12: 20 | I12: =$A12&"|"&$B12 -> Wed|Breakfast
A13: Wed | B13: Lunch | C13: Skyr Bowl with Salmon & Rice | D13: 192g Salmon fillet, 255g Skyr (plain), 230g White rice (cooked), 128g Cucumber | E13: 741 | F13: 66 | G13: 79 | H13: 18 | I13: =$A13&"|"&$B13 -> Wed|Lunch
A14: Wed | B14: Dinner | C14: Salmon & Quinoa Clean Bowl | D14: 160g Salmon fillet, 77g Quinoa (dry), 128g Broccoli (steamed), 64g Edamame, 13g Olive oil | E14: 741 | F14: 49 | G14: 57 | H14: 28 | I14: =$A14&"|"&$B14 -> Wed|Dinner
A15: Wed | B15: Snack | C15: Quark with Banana & Oats | D15: 319g Quark (low-fat), 153g Banana, 38g Oats | E15: 472 | F15: 38 | G15: 66 | H15: 6 | I15: =$A15&"|"&$B15 -> Wed|Snack
... A31: Sun | B31: Snack | C31: Quark with Banana & Oats | D31: 319g Quark (low-fat), 153g Banana, 38g Oats | E31: 472 | F31: 38 | G31: 66 | H31: 6 | I31: =$A31&"|"&$B31 -> Sun|Snack

Sheet Weight
A1: WEIGHT & PROGRESS
A2: Weigh in once a week at a fixed time. Enter date + weight; the chart and dashboard update automatically.
A3: Date | B3: Weight (kg) | C3: Change (kg) | D3: Note
A4: 46271 | B4: 88.6
A5: 46278 | B5: 88.2 | C5: =IF(AND(B5<>"",B4<>""),B5-B4,"") -> -0.4
A6: 46285 | B6: 88.4 | C6: =IF(AND(B6<>"",B5<>""),B6-B5,"") -> 0.2
A7: 46292 | B7: 87.9 | C7: =IF(AND(B7<>"",B6<>""),B7-B6,"") -> -0.5
A8: 46299 | B8: 87.6 | C8: =IF(AND(B8<>"",B7<>""),B8-B7,"") -> -0.3
A9: 46306 | B9: 87.7 | C9: =IF(AND(B9<>"",B8<>""),B9-B8,"") -> 0.1
A10: 46313 | B10: 87.2 | C10: =IF(AND(B10<>"",B9<>""),B10-B9,"") -> -0.5
A11: 46320 | B11: 87 | C11: =IF(AND(B11<>"",B10<>""),B11-B10,"") -> -0.2
C12: =IF(AND(B12<>"",B11<>""),B12-B11,"")
C13: =IF(AND(B13<>"",B12<>""),B13-B12,"")
C14: =IF(AND(B14<>"",B13<>""),B14-B13,"")
C15: =IF(AND(B15<>"",B14<>""),B15-B14,"")
C16: =IF(AND(B16<>"",B15<>""),B16-B15,"")
C17: =IF(AND(B17<>"",B16<>""),B17-B16,"")
C18: =IF(AND(B18<>"",B17<>""),B18-B17,"")
C19: =IF(AND(B19<>"",B18<>""),B19-B18,"")
C20: =IF(AND(B20<>"",B19<>""),B20-B19,"")
C21: =IF(AND(B21<>"",B20<>""),B21-B20,"")
C22: =IF(AND(B22<>"",B21<>""),B22-B21,"")
C23: =IF(AND(B23<>"",B22<>""),B23-B22,"")
... C30: =IF(AND(B30<>"",B29<>""),B30-B29,"")

Sheet Shopping
A1: SHOPPING LIST
A2: Your weekly list, by category. Tick what you already have.
A3: Category | B3: Item | C3: Quantity | D3: Got it?
A4: Produce | B4: Banana | C4: 612 g
A5: Produce | B5: Courgette | C5: 519 g
A6: Produce | B6: Chopped tomatoes | C6: 519 g
A7: Produce | B7: Fresh spinach | C7: 512 g
A8: Produce | B8: Cucumber | C8: 512 g
A9: Produce | B9: Broccoli (steamed) | C9: 512 g
A10: Produce | B10: Mixed berries | C10: 345 g
A11: Produce | B11: Kale | C11: 105 g
A12: Protein | B12: Salmon fillet | C12: 1.4 kg
A13: Protein | B13: Firm tofu | C13: 693 g
A14: Protein | B14: Lentils (tinned) | C14: 345 g
A15: Protein | B15: Chickpeas (tinned) | C15: 345 g
... A32: Other | B32: Miso paste | C32: 51 g

Sheet Recipes
A1: RECIPES
A2: 10 chef-built recipes with macros and method. Macros are estimates for the amounts shown.
A4: 1 | B4: Savoury Oats with Egg
A5: Breakfast · Fibermaxxing / Recovery — 420 kcal · 22g P · 42g C · 16g F · 9g fibre
A6: INGREDIENTS
B7: Oats | D7: 50 g
B8: Low-fat stock | D8: 150 ml
B9: Fresh spinach | D9: 100 g
B10: Egg (poached) | D10: 1 (50 g)
B11: Pumpkin seeds | D11: 15 g
A12: METHOD
A13: 1 | B13: Bring the stock to a gentle simmer in a small pan.
A14: 2 | B14: Stir in the oats and cook 4–5 min, stirring, until creamy.
A15: 3 | B15: Fold through the spinach in the last minute until just wilted; season.
A16: 4 | B16: Meanwhile poach the egg ~3 min in simmering water with a splash of vinegar.
A17: 5 | B17: Spoon the oats into a bowl, top with the egg, scatter the pumpkin seeds and a crack of pepper.
A19: 2 | B19: Vegan Lentil-Chickpea Curry
A20: Dinner · Plant-based / Muscle gain — 510 kcal · 26g P · 58g C · 15g F · 14g fibre
A21: INGREDIENTS
B22: Lentils (tinned) | D22: 100 g
B23: Chickpeas (tinned) | D23: 100 g
B24: Chopped tomatoes | D24: 150 g
B25: Light coconut milk | D25: 50 ml
B26: Kale | D26: 30 g
B27: Curry spices | D27: 5 g
A28: METHOD
A29: 1 | B29: Warm a dash of oil in a pan and toast the curry spices ~30 sec until fragrant.
A30: 2 | B30: Add the chopped tomatoes and simmer 3–4 min to reduce slightly.
A31: 3 | B31: Stir in the drained lentils and chickpeas; simmer 5 min.
A32: 4 | B32: Pour in the coconut milk, add the kale, and cook 2–3 min until the kale softens.
A33: 5 | B33: Season with salt; finish with lemon or coriander. Serve as is or with rice.
A35: 3 | B35: Matcha Protein Overnight Oats
A36: Breakfast · Focus / Pre-workout — 460 kcal · 32g P · 48g C · 12g F · 8g fibre
A37: INGREDIENTS
B38: Oats | D38: 45 g
B39: Vanilla protein powder | D39: 30 g
B40: Matcha powder | D40: 2 g
B41: Chia seeds | D41: 10 g
B42: Almond milk | D42: 150 ml
A43: METHOD
...
