Workbook

Sheet Dashboard
A1: H | B1: HYBRIDFUELCO | I1: VOORTGANGSTRACKER | N1: =IFERROR(LOOKUP(2,1/(Gewicht!$B$4:$B$30<>""),Gewicht!$B$4:$B$30),"") -> 87
N2: =IFERROR(LOOKUP(2,1/(Gewicht!$C$4:$C$30<>""),Gewicht!$C$4:$C$30),"") -> -0.2
N3: =IF(AND(N1<>"",N2<>""),N2/N1,"") -> -0.0022988506
A4: Huidig gewicht | D4: Laatste verandering | G4: Status | J4: Vandaag
A5: =N1 -> 87 | D5: =N2 -> -0.2 | G5: =IF(N3="","",IF(N3<-0.01,"! Te snel",IF(N3<-0.003,"✓ Op koers",IF(N3<=0.003,"– Stabiel",IF(N3<=0.01,"✓ Op koers","! Te snel"))))) -> – Stabiel | J5: =SUMIFS(Weekplan!$E$4:$E$31,Weekplan!$A$4:$A$31,$K$8) -> 2220
A8: Gewichtsverloop | G8: Vandaag — eten | K8: Ma
H9: Ontbijt | I9: =IFERROR(INDEX(Weekplan!$C$4:$C$31,MATCH($K$8&"|"&"Ontbijt",Weekplan!$I$4:$I$31,0)),"") -> Hartige havermout met ei | L9: =IFERROR(INDEX(Weekplan!$E$4:$E$31,MATCH($K$8&"|"&"Ontbijt",Weekplan!$I$4:$I$31,0)),"") -> 640
H10: Lunch | I10: =IFERROR(INDEX(Weekplan!$C$4:$C$31,MATCH($K$8&"|"&"Lunch",Weekplan!$I$4:$I$31,0)),"") -> Kip & rijst bowl | L10: =IFERROR(INDEX(Weekplan!$E$4:$E$31,MATCH($K$8&"|"&"Lunch",Weekplan!$I$4:$I$31,0)),"") -> 560
H11: Diner | I11: =IFERROR(INDEX(Weekplan!$C$4:$C$31,MATCH($K$8&"|"&"Diner",Weekplan!$I$4:$I$31,0)),"") -> Mager gehakt met pasta | L11: =IFERROR(INDEX(Weekplan!$E$4:$E$31,MATCH($K$8&"|"&"Diner",Weekplan!$I$4:$I$31,0)),"") -> 720
H12: Snack | I12: =IFERROR(INDEX(Weekplan!$C$4:$C$31,MATCH($K$8&"|"&"Snack",Weekplan!$I$4:$I$31,0)),"") -> Kwark met noten | L12: =IFERROR(INDEX(Weekplan!$E$4:$E$31,MATCH($K$8&"|"&"Snack",Weekplan!$I$4:$I$31,0)),"") -> 300
G13: Dagtotaal | J13: =SUMIFS(Weekplan!$E$4:$E$31,Weekplan!$A$4:$A$31,$K$8) -> 2220
A16: =IF(N3="","Verantwoord tempo — ~0,5–1% per week. Zo behoud je spier en herstel.",IF(OR(N3<-0.01,N3>0.01),"Je verandert sneller dan 1% per week. Stel je calorieën iets bij.",IF(N3>-0.003,"Weinig verandering. Geduld, of stel je calorieën iets bij.","Verantwoord tempo — ~0,5–1% per week. Zo behoud je spier en herstel."))) -> Weinig verandering. Geduld, of stel je calorieën iets bij.
A18: Dagmacro's — gekozen dag
A19: Eiwit | E19: Koolhydraten | I19: Vet
A20: =SUMIFS(Weekplan!$F$4:$F$31,Weekplan!$A$4:$A$31,$K$8) -> 148 | E20: =SUMIFS(Weekplan!$G$4:$G$31,Weekplan!$A$4:$A$31,$K$8) -> 239 | I20: =SUMIFS(Weekplan!$H$4:$H$31,Weekplan!$A$4:$A$31,$K$8) -> 60

Sheet Weekplan
A1: WEEKPLAN
A2: Vervang deze voorbeeldweek door je eigen plan uit de app. Het dashboard leest 'Vandaag' hieruit.
A3: Dag | B3: Type | C3: Gerecht | D3: Ingrediënten | E3: kcal | F3: Eiwit (g) | G3: Koolh. (g) | H3: Vet (g) | I3: key
A4: Ma | B4: Ontbijt | C4: Hartige havermout met ei | D4: 60g havermout, 2 eieren, 100g spinazie | E4: 640 | F4: 30 | G4: 82 | H4: 18 | I4: =$A4&"|"&$B4 -> Ma|Ontbijt
A5: Ma | B5: Lunch | C5: Kip & rijst bowl | D5: 150g kip, 70g rijst, 150g groente | E5: 560 | F5: 48 | G5: 55 | H5: 12 | I5: =$A5&"|"&$B5 -> Ma|Lunch
A6: Ma | B6: Diner | C6: Mager gehakt met pasta | D6: 130g gehakt, 70g pasta, tomatensaus | E6: 720 | F6: 42 | G6: 92 | H6: 16 | I6: =$A6&"|"&$B6 -> Ma|Diner
A7: Ma | B7: Snack | C7: Kwark met noten | D7: 200g kwark, 20g noten | E7: 300 | F7: 28 | G7: 10 | H7: 14 | I7: =$A7&"|"&$B7 -> Ma|Snack
A8: Di | B8: Ontbijt | C8: Kwark met havermout & bes | D8: 250g kwark, 40g havermout, 100g bes | E8: 430 | F8: 42 | G8: 45 | H8: 6 | I8: =$A8&"|"&$B8 -> Di|Ontbijt
A9: Di | B9: Lunch | C9: Tonijnwrap | D9: 1 wrap, 100g tonijn, 50g mais | E9: 470 | F9: 38 | G9: 48 | H9: 10 | I9: =$A9&"|"&$B9 -> Di|Lunch
A10: Di | B10: Diner | C10: Zalm met quinoa | D10: 125g zalm, 60g quinoa, 100g broccoli | E10: 640 | F10: 40 | G10: 45 | H10: 26 | I10: =$A10&"|"&$B10 -> Di|Diner
A11: Di | B11: Snack | C11: Proteïnereep & fruit | D11: 1 reep, 1 appel | E11: 280 | F11: 20 | G11: 32 | H11: 7 | I11: =$A11&"|"&$B11 -> Di|Snack
A12: Wo | B12: Ontbijt | C12: Eiwitpannenkoeken | D12: 50g havermeel, 30g whey, 1 ei | E12: 600 | F12: 38 | G12: 76 | H12: 10 | I12: =$A12&"|"&$B12 -> Wo|Ontbijt
A13: Wo | B13: Lunch | C13: Rund & avocado bowl | D13: 150g rundergehakt, 80g avocado, 80g sla | E13: 600 | F13: 45 | G13: 22 | H13: 30 | I13: =$A13&"|"&$B13 -> Wo|Lunch
A14: Wo | B14: Diner | C14: Kipfilet met zoete aardappel | D14: 160g kip, 200g zoete aardappel, 150g groente | E14: 740 | F14: 50 | G14: 88 | H14: 14 | I14: =$A14&"|"&$B14 -> Wo|Diner
A15: Wo | B15: Snack | C15: Skyr met honing | D15: 200g skyr, 15g honing | E15: 240 | F15: 22 | G15: 24 | H15: 2 | I15: =$A15&"|"&$B15 -> Wo|Snack
... A31: Zo | B31: Snack | C31: Kwark met noten | D31: 200g kwark, 20g noten | E31: 300 | F31: 28 | G31: 10 | H31: 14 | I31: =$A31&"|"&$B31 -> Zo|Snack

Sheet Gewicht
A1: GEWICHT & VOORTGANG
A2: Weeg je 1x per week op een vast moment. Vul datum + gewicht in; de grafiek en het dashboard updaten vanzelf.
A3: Datum | B3: Gewicht (kg) | C3: Verschil (kg) | D3: Notitie | F3: BMI-TOOL
A4: 46271 | B4: 88.6 | F4: Lengte (cm) | H4: ← vul in
A5: 46278 | B5: 88.2 | C5: =IF(AND(B5<>"",B4<>""),B5-B4,"") -> -0.4 | F5: Laatste gewicht (kg) | G5: =IFERROR(LOOKUP(2,1/(B4:B30<>""),B4:B30),"") -> 87
A6: 46285 | B6: 88.4 | C6: =IF(AND(B6<>"",B5<>""),B6-B5,"") -> 0.2 | F6: BMI | G6: =IF(AND(G4>0,G5>0),ROUND(G5/(G4/100)^2,1),"")
A7: 46292 | B7: 87.9 | C7: =IF(AND(B7<>"",B6<>""),B7-B6,"") -> -0.5 | F7: Categorie | G7: =IF(G6="","",IF(G6<18.5,"Ondergewicht",IF(G6<25,"Gezond",IF(G6<30,"Overgewicht","Obesitas"))))
A8: 46299 | B8: 87.6 | C8: =IF(AND(B8<>"",B7<>""),B8-B7,"") -> -0.3
A9: 46306 | B9: 87.7 | C9: =IF(AND(B9<>"",B8<>""),B9-B8,"") -> 0.1 | F9: BMI = gewicht ÷ lengte². Ruwe maat (spiermassa telt niet mee). Onder 18,5 = ondergewicht — dan niet verder afvallen.
A10: 46313 | B10: 87.2 | C10: =IF(AND(B10<>"",B9<>""),B10-B9,"") -> -0.5
A11: 46320 | B11: 87 | C11: =IF(AND(B11<>"",B10<>""),B11-B10,"") -> -0.2
C12: =IF(AND(B12<>"",B11<>""),B12-B11,"")
C13: =IF(AND(B13<>"",B12<>""),B13-B12,"")
C14: =IF(AND(B14<>"",B13<>""),B14-B13,"")
C15: =IF(AND(B15<>"",B14<>""),B15-B14,"")
C16: =IF(AND(B16<>"",B15<>""),B16-B15,"")
C17: =IF(AND(B17<>"",B16<>""),B17-B16,"")
C18: =IF(AND(B18<>"",B17<>""),B18-B17,"")
C19: =IF(AND(B19<>"",B18<>""),B19-B18,"")
C20: =IF(AND(B20<>"",B19<>""),B20-B19,"")
C21: =IF(AND(B21<>"",B20<>""),B21-B20,"")
C22: =IF(AND(B22<>"",B21<>""),B22-B21,"")
C23: =IF(AND(B23<>"",B22<>""),B23-B22,"")
... C30: =IF(AND(B30<>"",B29<>""),B30-B29,"")

Sheet Boodschappen
A1: BOODSCHAPPEN
A2: Je weeklijst, per categorie. Vink af wat je in huis hebt.
A3: Categorie | B3: Product | C3: Hoeveelheid | D3: In huis?
A4: Groente & Fruit | B4: Spinazie 500g
A5: Groente & Fruit | B5: Broccoli 400g
A6: Groente & Fruit | B6: Appels 7st
A7: Groente & Fruit | B7: Bessen 300g
A8: Vlees & Vis | B8: Kipfilet 1kg
A9: Vlees & Vis | B9: Rundergehakt 500g
A10: Vlees & Vis | B10: Zalmfilet 400g
A11: Zuivel | B11: Magere kwark 1kg
A12: Zuivel | B12: Skyr 500g
A13: Zuivel | B13: Eieren 12st
A14: Granen | B14: Havermout 500g
A15: Granen | B15: Rijst 500g
A16: Granen | B16: Pasta 500g

Sheet Recepten
A1: RECEPTEN
A2: 10 kok-recepten met macro's en bereiding. Macro's zijn schattingen voor de genoemde hoeveelheden.
A4: 1 | B4: Hartige Havermout met Ei
A5: Ontbijt · Fibermaxxing / Herstel — 420 kcal · 22g P · 42g C · 16g F · 9g vezels
A6: INGREDIËNTEN
B7: Havermout | D7: 50 g
B8: Vetarme bouillon | D8: 150 ml
B9: Verse spinazie | D9: 100 g
B10: Ei (gepocheerd) | D10: 1 (50 g)
B11: Pompoenpitten | D11: 15 g
A12: BEREIDING
A13: 1 | B13: Breng de bouillon in een steelpan tegen de kook aan.
A14: 2 | B14: Roer de havermout erdoor en kook 4–5 min, al roerend, tot romig.
A15: 3 | B15: Schep de laatste minuut de spinazie erdoor tot net geslonken; breng op smaak.
A16: 4 | B16: Pocheer ondertussen het ei ~3 min in zacht kokend water met een scheutje azijn.
A17: 5 | B17: Schep de havermout in een kom, leg het ei erop, strooi de pompoenpitten erover en wat peper.
A19: 2 | B19: Vegan Linzen-Kikkererwten Curry
A20: Diner · Plantaardig / Spieropbouw — 510 kcal · 26g P · 58g C · 15g F · 14g vezels
A21: INGREDIËNTEN
B22: Linzen (uit blik) | D22: 100 g
B23: Kikkererwten (uit blik) | D23: 100 g
B24: Tomatenblokjes | D24: 150 g
B25: Lichte kokosmelk | D25: 50 ml
B26: Boerenkool | D26: 30 g
B27: Currykruiden | D27: 5 g
A28: BEREIDING
A29: 1 | B29: Verwarm een scheutje olie; rooster de currykruiden ~30 sec tot ze geuren.
A30: 2 | B30: Voeg de tomatenblokjes toe en laat 3–4 min inkoken.
A31: 3 | B31: Roer de uitgelekte linzen en kikkererwten erdoor; laat 5 min pruttelen.
A32: 4 | B32: Giet de kokosmelk erbij, voeg de boerenkool toe en kook 2–3 min tot de kool zacht is.
A33: 5 | B33: Breng op smaak met zout; maak af met citroen of koriander. Serveer zo of met rijst.
A35: 3 | B35: Matcha Protein Overnight Oats
A36: Ontbijt · Focus / Pre-workout — 460 kcal · 32g P · 48g C · 12g F · 8g vezels
A37: INGREDIËNTEN
B38: Havermout | D38: 45 g
B39: Vanille-eiwitpoeder | D39: 30 g
B40: Matchapoeder | D40: 2 g
B41: Chiazaad | D41: 10 g
B42: Amandelmelk | D42: 150 ml
A43: BEREIDING
...
